Workbook

Sheet 0. Start Here
A1: 📘 FINANCE & BANKING — EXCEL PORTFOLIO PROJECT | Beginner Guide
B2: Welcome! This is a complete end-to-end project. Follow the steps below. Each sheet builds on the last — start with Raw Data, end with the Dashboard.
B3: PROJECT OVERVIEW
B4: Dataset | C4: 400 bank transactions — loans, deposits, credit cards across 5 branches (FY 2024)
B5: Domain | C5: Finance & Banking — realistic data an analyst would see at any retail bank
B6: Difficulty | C6: Beginner-friendly formulas · Perfect as your first data analytics portfolio piece
B7: What You Build | C7: Raw Data → Cleaning → Analysis → Pivot Tables → 4 Charts → Executive Dashboard
B9: STEP 1 | 1. Raw Data
B10: What to do | C10: Open this sheet and explore the 400 rows. Spot the 5 data quality issues listed at the bottom.
B11: Issues inside | C11: 1) Branch casing 2) Status leading spaces 3-4) Missing Amount/Rate 5) No date parts
B12: Key skill | C12: Data auditing — every real-world dataset needs inspection before analysis
B14: STEP 2 | 2. Clean Data
B15: PROPER() | C15: Converts 'DOWNTOWN' → 'Downtown'. Use: =PROPER(TRIM(A2))
B16: TRIM() | C16: Removes extra spaces. Use: =TRIM(A2) — fixes ' Active' → 'Active'
B17: IFERROR() | C17: Handles errors gracefully. Use: =IFERROR(formula, fallback_value)
B18: TEXT() | C18: Extracts month name from a date. Use: =TEXT(B2,"mmm") → 'Jan'
B19: INT() formula | C19: Calculates quarter: =INT((MONTH(B2)-1)/3+1) → returns 1, 2, 3, or 4
B20: PMT formula | C20: Monthly payment: =(L2*(M2/100/12))/(1-(1+M2/100/12)^(-N2)) — beginner finance formula!
B22: STEP 3 | 3. Analysis
B23: SUMIF() | C23: Adds values meeting ONE condition. =SUMIF(range, condition, sum_range)
B24: COUNTIF() | C24: Counts cells meeting ONE condition. =COUNTIF(range, condition)
B25: AVERAGEIF() | C25: Averages values meeting ONE condition. =AVERAGEIF(range, condition, avg_range)
B26: RANK() | C26: Ranks a value in a list. =RANK(value, all_values, 0) — 0 means descending
B27: MoM Growth | C27: Month-over-month: =(this_month - last_month) / last_month — fundamental finance metric
B29: STEP 4 | 4. Pivot Summary
B30: SUMPRODUCT() | C30: Most powerful beginner formula — sums with MULTIPLE conditions.
B31: Syntax | C31: =SUMPRODUCT((range1=condition1)*(range2=condition2)*(values))
B32: Why it matters | C32: Interviewers LOVE this. It replaces PivotTables with a formula.
B33: Practice tip | C33: Recreate Table 1 using Insert → PivotTable — do both methods!
B35: STEP 5 | 5. Charts
B36: Chart 1 | C36: Column chart — Branch portfolio comparison
B37: Chart 2 | C37: Pie chart — Product category split (Deposits vs Loans vs Cards)
B38: Chart 3 | C38: Line chart — Monthly portfolio trend
B39: Chart 4 | C39: Horizontal bar — Risk level comparison
B40: Best practice | C40: Always add: chart title, axis labels, and consistent colour scheme
B42: STEP 6 | 6. Dashboard
B43: KPI Cards | C43: 4 headline numbers — every finance dashboard starts with these
B44: Mini-tables | C44: Branch, Category, Risk breakdowns — linked to Clean Data automatically
B45: Dynamic | C45: Change any number in Clean Data — Dashboard updates instantly. This impresses!
B46: Screenshot it | C46: Take a screenshot for your CV, LinkedIn, and GitHub portfolio page
...

Sheet 1. Raw Data
A1: BANK TRANSACTION DATA — RAW (Contains Data Quality Issues)
A2: Transaction ID | B2: Date | C2: Branch | D2: Product | E2: Category | F2: Relationship Manager | G2: Status | H2: Risk Level | I2: Amount ($) | J2: Interest Rate (%) | K2: Term (Months) | L2: Customer Age | M2: Customer Segment
A3: TXN-100001 | B3: 2024-04-08 | C3: Eastgate | D3: Business Loan | E3: Loans | F3: James Patel | G3: Active | H3: Low | I3: 33744.48 | J3: 3.5 | K3: 120 | L3: 55 | M3: Standard
A4: TXN-100002 | B4: 2024-11-07 | C4: Eastgate | D4: Mortgage | E4: Loans | F4: Maria Lopez | G4: Pending | H4: Medium | I4: 38493 | J4: 10.1 | K4: 360 | L4: 43 | M4: Standard
A5: TXN-100003 | B5: 2024-01-14 | C5: Westside | D5: Business Loan | E5: Loans | F5: Sarah Chen | G5: Active | H5: High | I5: 51339.22 | J5: 13.88 | K5: 240 | L5: 27 | M5: Standard
A6: TXN-100004 | B6: 2024-12-26 | C6: Westside | D6: Personal Loan | E6: Loans | F6: James Patel | G6: Inactive | H6: Low | J6: 13.14 | K6: 24 | L6: 54 | M6: Premium
A7: TXN-100005 | B7: 2024-03-10 | C7: Eastgate | D7: Savings Account | E7: Deposits | F7: David Kim | G7: Inactive | H7: Low | I7: 154539.02 | J7: 6.88 | K7: 24 | L7: 55 | M7: Premium
A8: TXN-100006 | B8: 2024-06-23 | C8: Eastgate | D8: Credit Card | E8: Cards | F8: Rachel Moore | G8: Active | H8: Low | I8: 119297.77 | J8: 3.14 | K8: 360 | L8: 71 | M8: Premium
A9: TXN-100007 | B9: 2024-03-07 | C9: Uptown | D9: Credit Card | E9: Cards | F9: James Patel | G9: Active | H9: Medium | I9: 220167.46 | J9: 6.17 | K9: 180 | L9: 73 | M9: Premium
A10: TXN-100008 | B10: 2024-06-07 | C10: Downtown | D10: Credit Card | E10: Cards | F10: Sarah Chen | G10: Active | H10: Low | I10: 94555.08 | J10: 6.37 | K10: 120 | L10: 46 | M10: Standard
A11: TXN-100009 | B11: 2024-11-08 | C11: Westside | D11: Business Loan | E11: Loans | F11: David Kim | G11: Active | H11: Medium | I11: 163514.23 | J11: 6.07 | K11: 60 | L11: 35 | M11: Premium
A12: TXN-100010 | B12: 2024-02-17 | C12: Eastgate | D12: Savings Account | E12: Deposits | F12: David Kim | G12: Active | H12: Medium | I12: 73610.93 | J12: 10.38 | K12: 60 | L12: 72 | M12: Standard
A13: TXN-100011 | B13: 2024-07-22 | C13: Westside | D13: Business Loan | E13: Loans | F13: Rachel Moore | G13: Active | H13: Medium | I13: 169748.38 | J13: 12.42 | K13: 360 | L13: 64 | M13: Premium
A14: TXN-100012 | B14: 2024-11-22 | C14: Downtown | D14: Auto Loan | E14: Loans | F14: Maria Lopez | G14: Pending | H14: Low | I14: 43328.88 | J14: 9.86 | K14: 120 | L14: 69 | M14: Standard
A15: TXN-100013 | B15: 2024-04-01 | C15: Eastgate | D15: Checking Account | E15: Deposits | F15: Sarah Chen | G15: Active | H15: High | I15: 130763.98 | J15: 13.42 | K15: 24 | L15: 54 | M15: Premium
A16: TXN-100014 | B16: 2024-11-27 | C16: EASTGATE | D16: Fixed Deposit | E16: Deposits | F16: Rachel Moore | G16: Active | H16: High | I16: 191377.88 | J16: 11.34 | K16: 36 | L16: 69 | M16: Premium
A17: TXN-100015 | B17: 2024-11-23 | C17: Downtown | D17: Business Loan | E17: Loans | F17: Maria Lopez | G17: Active | H17: High | I17: 147208.83 | J17: 5.89 | K17: 12 | L17: 72 | M17: Premium
A18: TXN-100016 | B18: 2024-12-06 | C18: Uptown | D18: Fixed Deposit | E18: Deposits | F18: David Kim | G18: Active | H18: High | I18: 90279.87 | J18: 4.89 | K18: 180 | L18: 58 | M18: Standard
... A31: TXN-100029 | B31: 2024-04-22 | C31: Northpark | D31: Savings Account | E31: Deposits | F31: James Patel | G31: Active | H31: High | I31: 176395.17 | J31: 7.05 | K31: 240 | L31: 26 | M31: Premium
A32: TXN-100030 | B32: 2024-06-07 | C32: Downtown | D32: Checking Account | E32: Deposits | F32: Sarah Chen | G32: Active | H32: Low | J32: 10.12 | K32: 24 | L32: 39 | M32: Premium
A33: TXN-100031 | B33: 2024-07-05 | C33: Uptown | D33: Auto Loan | E33: Loans | F33: Sarah Chen | G33: Active | H33: Medium | I33: 174300.23 | J33: 8.6 | K33: 36 | L33: 50 | M33: Premium
A34: TXN-100032 | B34: 2024-07-08 | C34: Downtown | D34: Business Loan | E34: Loans | F34: Sarah Chen | G34: Active | H34: Medium | I34: 134809.56 | J34: 11.47 | K34: 6 | L34: 23 | M34: Premium
A35: TXN-100033 | B35: 2024-02-23 | C35: Downtown | D35: Checking Account | E35: Deposits | F35: David Kim | G35: Active | H35: Medium | I35: 211082.87 | J35: 10.86 | K35: 180 | L35: 49 | M35: Premium
A36: TXN-100034 | B36: 2024-04-03 | C36: Westside | D36: Auto Loan | E36: Loans | F36: Sarah Chen | G36: Active | H36: High | I36: 232615.16 | J36: 5.03 | K36: 60 | L36: 61 | M36: Premium
A37: TXN-100035 | B37: 2024-12-09 | C37: Eastgate | D37: Fixed Deposit | E37: Deposits | F37: Rachel Moore | G37: Active | H37: High | I37: 19870.29 | J37: 6.91 | K37: 6 | L37: 40 | M37: Basic
A38: TXN-100036 | B38: 2024-02-10 | C38: Westside | D38: Mortgage | E38: Loans | F38: Rachel Moore | G38: Inactive | H38: High | I38: 99894.86 | J38: 4.9 | K38: 360 | L38: 39 | M38: Standard
A39: TXN-100037 | B39: 2024-07-07 | C39: DOWNTOWN | D39: Checking Account | E39: Deposits | F39: Rachel Moore | G39: Active | H39: Low | I39: 106129.92 | J39: 10.12 | K39: 360 | L39: 59 | M39: Premium
A40: TXN-100038 | B40: 2024-03-27 | C40: Downtown | D40: Checking Account | E40: Deposits | F40: David Kim | G40: Pending | H40: Medium | I40: 34141.6 | J40: 11.4 | K40: 48 | L40: 33 | M40: Standard
A41: TXN-100039 | B41: 2024-05-09 | C41: Eastgate | D41: Savings Account | E41: Deposits | F41: Sarah Chen | G41: Active | H41: High | I41: 212293.98 | J41: 10.86 | K41: 48 | L41: 68 | M41: Premium
A42: TXN-100040 | B42: 2024-04-28 | C42: Eastgate | D42: Personal Loan | E42: Loans | F42: Maria Lopez | G42: Active | H42: Medium | I42: 249203.95 | J42: 11.35 | K42: 48 | L42: 75 | M42: Premium
A43: TXN-100041 | B43: 2024-09-08 | C43: Uptown | D43: Mortgage | E43: Loans | F43: Maria Lopez | G43: Active | H43: Low | I43: 153606.39 | J43: 9.42 | K43: 12 | L43: 36 | M43: Premium
A44: TXN-100042 | B44: 2024-07-15 | C44: Eastgate | D44: Savings Account | E44: Deposits | F44: Sarah Chen | G44: Active | H44: Low | I44: 27111.12 | J44: 2.56 | K44: 12 | L44: 71 | M44: Standard
... A56: TXN-100054 | B56: 2024-09-27 | C56: Downtown | D56: Auto Loan | E56: Loans | F56: Rachel Moore | G56: Pending | H56: Medium | I56: 50622.52 | J56: 7.27 | K56: 48 | L56: 33 | M56: Standard
A57: TXN-100055 | B57: 2024-03-25 | C57: Westside | D57: Credit Card | E57: Cards | F57: David Kim | G57: Active | H57: High | I57: 243887.25 | K57: 36 | L57: 33 | M57: Premium
A58: TXN-100056 | B58: 2024-07-12 | C58: Northpark | D58: Mortgage | E58: Loans | F58: Maria Lopez | G58: Active | H58: Medium | I58: 100573.87 | J58: 12.67 | K58: 60 | L58: 72 | M58: Premium
A59: TXN-100057 | B59: 2024-03-23 | C59: Eastgate | D59: Auto Loan | E59: Loans | F59: James Patel | G59: Active | H59: High | I59: 154461.28 | J59: 8.29 | K59: 240 | L59: 64 | M59: Premium
A60: TXN-100058 | B60: 2024-06-07 | C60: Eastgate | D60: Auto Loan | E60: Loans | F60: David Kim | G60: Active | H60: Medium | I60: 176157.79 | J60: 3.53 | K60: 36 | L60: 72 | M60: Premium
A61: TXN-100059 | B61: 2024-12-02 | C61: Uptown | D61: Auto Loan | E61: Loans | F61: Sarah Chen | G61: Active | H61: Low | I61: 21996.18 | J61: 7.91 | K61: 36 | L61: 68 | M61: Basic
A62: TXN-100060 | B62: 2024-06-09 | C62: Northpark | D62: Business Loan | E62: Loans | F62: Rachel Moore | G62: Pending | H62: Medium | I62: 184311.2 | J62: 4.44 | K62: 24 | L62: 52 | M62: Premium
A63: TXN-100061 | B63: 2024-08-20 | C63: Eastgate | D63: Fixed Deposit | E63: Deposits | F63: James Patel | G63: Active | H63: High | I63: 149148.93 | J63: 8.66 | K63: 360 | L63: 51 | M63: Premium
...

Sheet 2. Clean Data
A1: BANK TRANSACTION DATA — CLEANED & ENRICHED
A2: Transaction ID | B2: Date | C2: Month | D2: Quarter | E2: Year | F2: Branch | G2: Product | H2: Category | I2: Relationship Manager | J2: Status | K2: Risk Level | L2: Amount ($) | M2: Interest Rate (%) | N2: Term (Months) | O2: Monthly Payment ($) | P2: Customer Age | Q2: Customer Segment
A3: ='1. Raw Data'!A3 -> TXN-100001 | B3: =IFERROR(DATEVALUE('1. Raw Data'!B3),"") -> 45390 | C3: =IFERROR(TEXT(B3,"mmm"),"") -> Apr | D3: =IFERROR("Q"&INT((MONTH(B3)-1)/3+1),"") -> Q2 | E3: =IFERROR(YEAR(B3),"") -> 2024 | F3: =PROPER(TRIM('1. Raw Data'!C3)) -> Eastgate | G3: =TRIM('1. Raw Data'!D3) -> Business Loan | H3: =TRIM('1. Raw Data'!E3) -> Loans | I3: =TRIM('1. Raw Data'!F3) -> James Patel | J3: =PROPER(TRIM('1. Raw Data'!G3)) -> Active | K3: =TRIM('1. Raw Data'!H3) -> Low | L3: =IFERROR(IF('1. Raw Data'!I3="",AVERAGE(IF('1. Raw Data'!I3:I402<>"",'1. Raw Data'!I3:I402)),VALUE('1. Raw Data'!I3)),0) -> 33744.48 | M3: =IFERROR(IF('1. Raw Data'!J3="",AVERAGE(IF('1. Raw Data'!J3:J402<>"",'1. Raw Data'!J3:J402)),VALUE('1. Raw Data'!J3)),0) -> 3.5 | N3: ='1. Raw Data'!K3 -> 120 | O3: =IFERROR(IF(M3=0,0,(L3*(M3/100/12))/(1-(1+M3/100/12)^(-N3))),0) -> 333.68522 | P3: ='1. Raw Data'!L3 -> 55 | Q3: =TRIM('1. Raw Data'!M3) -> Standard
A4: ='1. Raw Data'!A4 -> TXN-100002 | B4: =IFERROR(DATEVALUE('1. Raw Data'!B4),"") -> 45603 | C4: =IFERROR(TEXT(B4,"mmm"),"") -> Nov | D4: =IFERROR("Q"&INT((MONTH(B4)-1)/3+1),"") -> Q4 | E4: =IFERROR(YEAR(B4),"") -> 2024 | F4: =PROPER(TRIM('1. Raw Data'!C4)) -> Eastgate | G4: =TRIM('1. Raw Data'!D4) -> Mortgage | H4: =TRIM('1. Raw Data'!E4) -> Loans | I4: =TRIM('1. Raw Data'!F4) -> Maria Lopez | J4: =PROPER(TRIM('1. Raw Data'!G4)) -> Pending | K4: =TRIM('1. Raw Data'!H4) -> Medium | L4: =IFERROR(IF('1. Raw Data'!I4="",AVERAGE(IF('1. Raw Data'!I3:I402<>"",'1. Raw Data'!I3:I402)),VALUE('1. Raw Data'!I4)),0) -> 38493 | M4: =IFERROR(IF('1. Raw Data'!J4="",AVERAGE(IF('1. Raw Data'!J3:J402<>"",'1. Raw Data'!J3:J402)),VALUE('1. Raw Data'!J4)),0) -> 10.1 | N4: ='1. Raw Data'!K4 -> 360 | O4: =IFERROR(IF(M4=0,0,(L4*(M4/100/12))/(1-(1+M4/100/12)^(-N4))),0) -> 340.65158 | P4: ='1. Raw Data'!L4 -> 43 | Q4: =TRIM('1. Raw Data'!M4) -> Standard
A5: ='1. Raw Data'!A5 -> TXN-100003 | B5: =IFERROR(DATEVALUE('1. Raw Data'!B5),"") -> 45305 | C5: =IFERROR(TEXT(B5,"mmm"),"") -> Jan | D5: =IFERROR("Q"&INT((MONTH(B5)-1)/3+1),"") -> Q1 | E5: =IFERROR(YEAR(B5),"") -> 2024 | F5: =PROPER(TRIM('1. Raw Data'!C5)) -> Westside | G5: =TRIM('1. Raw Data'!D5) -> Business Loan | H5: =TRIM('1. Raw Data'!E5) -> Loans | I5: =TRIM('1. Raw Data'!F5) -> Sarah Chen | J5: =PROPER(TRIM('1. Raw Data'!G5)) -> Active | K5: =TRIM('1. Raw Data'!H5) -> High | L5: =IFERROR(IF('1. Raw Data'!I5="",AVERAGE(IF('1. Raw Data'!I3:I402<>"",'1. Raw Data'!I3:I402)),VALUE('1. Raw Data'!I5)),0) -> 51339.22 | M5: =IFERROR(IF('1. Raw Data'!J5="",AVERAGE(IF('1. Raw Data'!J3:J402<>"",'1. Raw Data'!J3:J402)),VALUE('1. Raw Data'!J5)),0) -> 13.88 | N5: ='1. Raw Data'!K5 -> 240 | O5: =IFERROR(IF(M5=0,0,(L5*(M5/100/12))/(1-(1+M5/100/12)^(-N5))),0) -> 633.94437 | P5: ='1. Raw Data'!L5 -> 27 | Q5: =TRIM('1. Raw Data'!M5) -> Standard
A6: ='1. Raw Data'!A6 -> TXN-100004 | B6: =IFERROR(DATEVALUE('1. Raw Data'!B6),"") -> 45652 | C6: =IFERROR(TEXT(B6,"mmm"),"") -> Dec | D6: =IFERROR("Q"&INT((MONTH(B6)-1)/3+1),"") -> Q4 | E6: =IFERROR(YEAR(B6),"") -> 2024 | F6: =PROPER(TRIM('1. Raw Data'!C6)) -> Westside | G6: =TRIM('1. Raw Data'!D6) -> Personal Loan | H6: =TRIM('1. Raw Data'!E6) -> Loans | I6: =TRIM('1. Raw Data'!F6) -> James Patel | J6: =PROPER(TRIM('1. Raw Data'!G6)) -> Inactive | K6: =TRIM('1. Raw Data'!H6) -> Low | L6: =IFERROR(IF('1. Raw Data'!I6="",AVERAGE(IF('1. Raw Data'!I3:I402<>"",'1. Raw Data'!I3:I402)),VALUE('1. Raw Data'!I6)),0) -> 0 | M6: =IFERROR(IF('1. Raw Data'!J6="",AVERAGE(IF('1. Raw Data'!J3:J402<>"",'1. Raw Data'!J3:J402)),VALUE('1. Raw Data'!J6)),0) -> 13.14 | N6: ='1. Raw Data'!K6 -> 24 | O6: =IFERROR(IF(M6=0,0,(L6*(M6/100/12))/(1-(1+M6/100/12)^(-N6))),0) -> 0 | P6: ='1. Raw Data'!L6 -> 54 | Q6: =TRIM('1. Raw Data'!M6) -> Premium
A7: ='1. Raw Data'!A7 -> TXN-100005 | B7: =IFERROR(DATEVALUE('1. Raw Data'!B7),"") -> 45361 | C7: =IFERROR(TEXT(B7,"mmm"),"") -> Mar | D7: =IFERROR("Q"&INT((MONTH(B7)-1)/3+1),"") -> Q1 | E7: =IFERROR(YEAR(B7),"") -> 2024 | F7: =PROPER(TRIM('1. Raw Data'!C7)) -> Eastgate | G7: =TRIM('1. Raw Data'!D7) -> Savings Account | H7: =TRIM('1. Raw Data'!E7) -> Deposits | I7: =TRIM('1. Raw Data'!F7) -> David Kim | J7: =PROPER(TRIM('1. Raw Data'!G7)) -> Inactive | K7: =TRIM('1. Raw Data'!H7) -> Low | L7: =IFERROR(IF('1. Raw Data'!I7="",AVERAGE(IF('1. Raw Data'!I3:I402<>"",'1. Raw Data'!I3:I402)),VALUE('1. Raw Data'!I7)),0) -> 154539.02 | M7: =IFERROR(IF('1. Raw Data'!J7="",AVERAGE(IF('1. Raw Data'!J3:J402<>"",'1. Raw Data'!J3:J402)),VALUE('1. Raw Data'!J7)),0) -> 6.88 | N7: ='1. Raw Data'!K7 -> 24 | O7: =IFERROR(IF(M7=0,0,(L7*(M7/100/12))/(1-(1+M7/100/12)^(-N7))),0) -> 6910.7065 | P7: ='1. Raw Data'!L7 -> 55 | Q7: =TRIM('1. Raw Data'!M7) -> Premium
A8: ='1. Raw Data'!A8 -> TXN-100006 | B8: =IFERROR(DATEVALUE('1. Raw Data'!B8),"") -> 45466 | C8: =IFERROR(TEXT(B8,"mmm"),"") -> Jun | D8: =IFERROR("Q"&INT((MONTH(B8)-1)/3+1),"") -> Q2 | E8: =IFERROR(YEAR(B8),"") -> 2024 | F8: =PROPER(TRIM('1. Raw Data'!C8)) -> Eastgate | G8: =TRIM('1. Raw Data'!D8) -> Credit Card | H8: =TRIM('1. Raw Data'!E8) -> Cards | I8: =TRIM('1. Raw Data'!F8) -> Rachel Moore | J8: =PROPER(TRIM('1. Raw Data'!G8)) -> Active | K8: =TRIM('1. Raw Data'!H8) -> Low | L8: =IFERROR(IF('1. Raw Data'!I8="",AVERAGE(IF('1. Raw Data'!I3:I402<>"",'1. Raw Data'!I3:I402)),VALUE('1. Raw Data'!I8)),0) -> 119297.77 | M8: =IFERROR(IF('1. Raw Data'!J8="",AVERAGE(IF('1. Raw Data'!J3:J402<>"",'1. Raw Data'!J3:J402)),VALUE('1. Raw Data'!J8)),0) -> 3.14 | N8: ='1. Raw Data'!K8 -> 360 | O8: =IFERROR(IF(M8=0,0,(L8*(M8/100/12))/(1-(1+M8/100/12)^(-N8))),0) -> 512.01652 | P8: ='1. Raw Data'!L8 -> 71 | Q8: =TRIM('1. Raw Data'!M8) -> Premium
A9: ='1. Raw Data'!A9 -> TXN-100007 | B9: =IFERROR(DATEVALUE('1. Raw Data'!B9),"") -> 45358 | C9: =IFERROR(TEXT(B9,"mmm"),"") -> Mar | D9: =IFERROR("Q"&INT((MONTH(B9)-1)/3+1),"") -> Q1 | E9: =IFERROR(YEAR(B9),"") -> 2024 | F9: =PROPER(TRIM('1. Raw Data'!C9)) -> Uptown | G9: =TRIM('1. Raw Data'!D9) -> Credit Card | H9: =TRIM('1. Raw Data'!E9) -> Cards | I9: =TRIM('1. Raw Data'!F9) -> James Patel | J9: =PROPER(TRIM('1. Raw Data'!G9)) -> Active | K9: =TRIM('1. Raw Data'!H9) -> Medium | L9: =IFERROR(IF('1. Raw Data'!I9="",AVERAGE(IF('1. Raw Data'!I3:I402<>"",'1. Raw Data'!I3:I402)),VALUE('1. Raw Data'!I9)),0) -> 220167.46 | M9: =IFERROR(IF('1. Raw Data'!J9="",AVERAGE(IF('1. Raw Data'!J3:J402<>"",'1. Raw Data'!J3:J402)),VALUE('1. Raw Data'!J9)),0) -> 6.17 | N9: ='1. Raw Data'!K9 -> 180 | O9: =IFERROR(IF(M9=0,0,(L9*(M9/100/12))/(1-(1+M9/100/12)^(-N9))),0) -> 1878.1799 | P9: ='1. Raw Data'!L9 -> 73 | Q9: =TRIM('1. Raw Data'!M9) -> Premium
A10: ='1. Raw Data'!A10 -> TXN-100008 | B10: =IFERROR(DATEVALUE('1. Raw Data'!B10),"") -> 45450 | C10: =IFERROR(TEXT(B10,"mmm"),"") -> Jun | D10: =IFERROR("Q"&INT((MONTH(B10)-1)/3+1),"") -> Q2 | E10: =IFERROR(YEAR(B10),"") -> 2024 | F10: =PROPER(TRIM('1. Raw Data'!C10)) -> Downtown | G10: =TRIM('1. Raw Data'!D10) -> Credit Card | H10: =TRIM('1. Raw Data'!E10) -> Cards | I10: =TRIM('1. Raw Data'!F10) -> Sarah Chen | J10: =PROPER(TRIM('1. Raw Data'!G10)) -> Active | K10: =TRIM('1. Raw Data'!H10) -> Low | L10: =IFERROR(IF('1. Raw Data'!I10="",AVERAGE(IF('1. Raw Data'!I3:I402<>"",'1. Raw Data'!I3:I402)),VALUE('1. Raw Data'!I10)),0) -> 94555.08 | M10: =IFERROR(IF('1. Raw Data'!J10="",AVERAGE(IF('1. Raw Data'!J3:J402<>"",'1. Raw Data'!J3:J402)),VALUE('1. Raw Data'!J10)),0) -> 6.37 | N10: ='1. Raw Data'!K10 -> 120 | O10: =IFERROR(IF(M10=0,0,(L10*(M10/100/12))/(1-(1+M10/100/12)^(-N10))),0) -> 1067.4101 | P10: ='1. Raw Data'!L10 -> 46 | Q10: =TRIM('1. Raw Data'!M10) -> Standard
A11: ='1. Raw Data'!A11 -> TXN-100009 | B11: =IFERROR(DATEVALUE('1. Raw Data'!B11),"") -> 45604 | C11: =IFERROR(TEXT(B11,"mmm"),"") -> Nov | D11: =IFERROR("Q"&INT((MONTH(B11)-1)/3+1),"") -> Q4 | E11: =IFERROR(YEAR(B11),"") -> 2024 | F11: =PROPER(TRIM('1. Raw Data'!C11)) -> Westside | G11: =TRIM('1. Raw Data'!D11) -> Business Loan | H11: =TRIM('1. Raw Data'!E11) -> Loans | I11: =TRIM('1. Raw Data'!F11) -> David Kim | J11: =PROPER(TRIM('1. Raw Data'!G11)) -> Active | K11: =TRIM('1. Raw Data'!H11) -> Medium | L11: =IFERROR(IF('1. Raw Data'!I11="",AVERAGE(IF('1. Raw Data'!I3:I402<>"",'1. Raw Data'!I3:I402)),VALUE('1. Raw Data'!I11)),0) -> 163514.23 | M11: =IFERROR(IF('1. Raw Data'!J11="",AVERAGE(IF('1. Raw Data'!J3:J402<>"",'1. Raw Data'!J3:J402)),VALUE('1. Raw Data'!J11)),0) -> 6.07 | N11: ='1. Raw Data'!K11 -> 60 | O11: =IFERROR(IF(M11=0,0,(L11*(M11/100/12))/(1-(1+M11/100/12)^(-N11))),0) -> 3166.5131 | P11: ='1. Raw Data'!L11 -> 35 | Q11: =TRIM('1. Raw Data'!M11) -> Premium
A12: ='1. Raw Data'!A12 -> TXN-100010 | B12: =IFERROR(DATEVALUE('1. Raw Data'!B12),"") -> 45339 | C12: =IFERROR(TEXT(B12,"mmm"),"") -> Feb | D12: =IFERROR("Q"&INT((MONTH(B12)-1)/3+1),"") -> Q1 | E12: =IFERROR(YEAR(B12),"") -> 2024 | F12: =PROPER(TRIM('1. Raw Data'!C12)) -> Eastgate | G12: =TRIM('1. Raw Data'!D12) -> Savings Account | H12: =TRIM('1. Raw Data'!E12) -> Deposits | I12: =TRIM('1. Raw Data'!F12) -> David Kim | J12: =PROPER(TRIM('1. Raw Data'!G12)) -> Active | K12: =TRIM('1. Raw Data'!H12) -> Medium | L12: =IFERROR(IF('1. Raw Data'!I12="",AVERAGE(IF('1. Raw Data'!I3:I402<>"",'1. Raw Data'!I3:I402)),VALUE('1. Raw Data'!I12)),0) -> 73610.93 | M12: =IFERROR(IF('1. Raw Data'!J12="",AVERAGE(IF('1. Raw Data'!J3:J402<>"",'1. Raw Data'!J3:J402)),VALUE('1. Raw Data'!J12)),0) -> 10.38 | N12: ='1. Raw Data'!K12 -> 60 | O12: =IFERROR(IF(M12=0,0,(L12*(M12/100/12))/(1-(1+M12/100/12)^(-N12))),0) -> 1577.8137 | P12: ='1. Raw Data'!L12 -> 72 | Q12: =TRIM('1. Raw Data'!M12) -> Standard
A13: ='1. Raw Data'!A13 -> TXN-100011 | B13: =IFERROR(DATEVALUE('1. Raw Data'!B13),"") -> 45495 | C13: =IFERROR(TEXT(B13,"mmm"),"") -> Jul | D13: =IFERROR("Q"&INT((MONTH(B13)-1)/3+1),"") -> Q3 | E13: =IFERROR(YEAR(B13),"") -> 2024 | F13: =PROPER(TRIM('1. Raw Data'!C13)) -> Westside | G13: =TRIM('1. Raw Data'!D13) -> Business Loan | H13: =TRIM('1. Raw Data'!E13) -> Loans | I13: =TRIM('1. Raw Data'!F13) -> Rachel Moore | J13: =PROPER(TRIM('1. Raw Data'!G13)) -> Active | K13: =TRIM('1. Raw Data'!H13) -> Medium | L13: =IFERROR(IF('1. Raw Data'!I13="",AVERAGE(IF('1. Raw Data'!I3:I402<>"",'1. Raw Data'!I3:I402)),VALUE('1. Raw Data'!I13)),0) -> 169748.38 | M13: =IFERROR(IF('1. Raw Data'!J13="",AVERAGE(IF('1. Raw Data'!J3:J402<>"",'1. Raw Data'!J3:J402)),VALUE('1. Raw Data'!J13)),0) -> 12.42 | N13: ='1. Raw Data'!K13 -> 360 | O13: =IFERROR(IF(M13=0,0,(L13*(M13/100/12))/(1-(1+M13/100/12)^(-N13))),0) -> 1801.1218 | P13: ='1. Raw Data'!L13 -> 64 | Q13: =TRIM('1. Raw Data'!M13) -> Premium
A14: ='1. Raw Data'!A14 -> TXN-100012 | B14: =IFERROR(DATEVALUE('1. Raw Data'!B14),"") -> 45618 | C14: =IFERROR(TEXT(B14,"mmm"),"") -> Nov | D14: =IFERROR("Q"&INT((MONTH(B14)-1)/3+1),"") -> Q4 | E14: =IFERROR(YEAR(B14),"") -> 2024 | F14: =PROPER(TRIM('1. Raw Data'!C14)) -> Downtown | G14: =TRIM('1. Raw Data'!D14) -> Auto Loan | H14: =TRIM('1. Raw Data'!E14) -> Loans | I14: =TRIM('1. Raw Data'!F14) -> Maria Lopez | J14: =PROPER(TRIM('1. Raw Data'!G14)) -> Pending | K14: =TRIM('1. Raw Data'!H14) -> Low | L14: =IFERROR(IF('1. Raw Data'!I14="",AVERAGE(IF('1. Raw Data'!I3:I402<>"",'1. Raw Data'!I3:I402)),VALUE('1. Raw Data'!I14)),0) -> 43328.88 | M14: =IFERROR(IF('1. Raw Data'!J14="",AVERAGE(IF('1. Raw Data'!J3:J402<>"",'1. Raw Data'!J3:J402)),VALUE('1. Raw Data'!J14)),0) -> 9.86 | N14: ='1. Raw Data'!K14 -> 120 | O14: =IFERROR(IF(M14=0,0,(L14*(M14/100/12))/(1-(1+M14/100/12)^(-N14))),0) -> 569.24053 | P14: ='1. Raw Data'!L14 -> 69 | Q14: =TRIM('1. Raw Data'!M14) -> Standard
A15: ='1. Raw Data'!A15 -> TXN-100013 | B15: =IFERROR(DATEVALUE('1. Raw Data'!B15),"") -> 45383 | C15: =IFERROR(TEXT(B15,"mmm"),"") -> Apr | D15: =IFERROR("Q"&INT((MONTH(B15)-1)/3+1),"") -> Q2 | E15: =IFERROR(YEAR(B15),"") -> 2024 | F15: =PROPER(TRIM('1. Raw Data'!C15)) -> Eastgate | G15: =TRIM('1. Raw Data'!D15) -> Checking Account | H15: =TRIM('1. Raw Data'!E15) -> Deposits | I15: =TRIM('1. Raw Data'!F15) -> Sarah Chen | J15: =PROPER(TRIM('1. Raw Data'!G15)) -> Active | K15: =TRIM('1. Raw Data'!H15) -> High | L15: =IFERROR(IF('1. Raw Data'!I15="",AVERAGE(IF('1. Raw Data'!I3:I402<>"",'1. Raw Data'!I3:I402)),VALUE('1. Raw Data'!I15)),0) -> 130763.98 | M15: =IFERROR(IF('1. Raw Data'!J15="",AVERAGE(IF('1. Raw Data'!J3:J402<>"",'1. Raw Data'!J3:J402)),VALUE('1. Raw Data'!J15)),0) -> 13.42 | N15: ='1. Raw Data'!K15 -> 24 | O15: =IFERROR(IF(M15=0,0,(L15*(M15/100/12))/(1-(1+M15/100/12)^(-N15))),0) -> 6242.5859 | P15: ='1. Raw Data'!L15 -> 54 | Q15: =TRIM('1. Raw Data'!M15) -> Premium
A16: ='1. Raw Data'!A16 -> TXN-100014 | B16: =IFERROR(DATEVALUE('1. Raw Data'!B16),"") -> 45623 | C16: =IFERROR(TEXT(B16,"mmm"),"") -> Nov | D16: =IFERROR("Q"&INT((MONTH(B16)-1)/3+1),"") -> Q4 | E16: =IFERROR(YEAR(B16),"") -> 2024 | F16: =PROPER(TRIM('1. Raw Data'!C16)) -> Eastgate | G16: =TRIM('1. Raw Data'!D16) -> Fixed Deposit | H16: =TRIM('1. Raw Data'!E16) -> Deposits | I16: =TRIM('1. Raw Data'!F16) -> Rachel Moore | J16: =PROPER(TRIM('1. Raw Data'!G16)) -> Active | K16: =TRIM('1. Raw Data'!H16) -> High | L16: =IFERROR(IF('1. Raw Data'!I16="",AVERAGE(IF('1. Raw Data'!I3:I402<>"",'1. Raw Data'!I3:I402)),VALUE('1. Raw Data'!I16)),0) -> 191377.88 | M16: =IFERROR(IF('1. Raw Data'!J16="",AVERAGE(IF('1. Raw Data'!J3:J402<>"",'1. Raw Data'!J3:J402)),VALUE('1. Raw Data'!J16)),0) -> 11.34 | N16: ='1. Raw Data'!K16 -> 36 | O16: =IFERROR(IF(M16=0,0,(L16*(M16/100/12))/(1-(1+M16/100/12)^(-N16))),0) -> 6296.3253 | P16: ='1. Raw Data'!L16 -> 69 | Q16: =TRIM('1. Raw Data'!M16) -> Premium
A17: ='1. Raw Data'!A17 -> TXN-100015 | B17: =IFERROR(DATEVALUE('1. Raw Data'!B17),"") -> 45619 | C17: =IFERROR(TEXT(B17,"mmm"),"") -> Nov | D17: =IFERROR("Q"&INT((MONTH(B17)-1)/3+1),"") -> Q4 | E17: =IFERROR(YEAR(B17),"") -> 2024 | F17: =PROPER(TRIM('1. Raw Data'!C17)) -> Downtown | G17: =TRIM('1. Raw Data'!D17) -> Business Loan | H17: =TRIM('1. Raw Data'!E17) -> Loans | I17: =TRIM('1. Raw Data'!F17) -> Maria Lopez | J17: =PROPER(TRIM('1. Raw Data'!G17)) -> Active | K17: =TRIM('1. Raw Data'!H17) -> High | L17: =IFERROR(IF('1. Raw Data'!I17="",AVERAGE(IF('1. Raw Data'!I3:I402<>"",'1. Raw Data'!I3:I402)),VALUE('1. Raw Data'!I17)),0) -> 147208.83 | M17: =IFERROR(IF('1. Raw Data'!J17="",AVERAGE(IF('1. Raw Data'!J3:J402<>"",'1. Raw Data'!J3:J402)),VALUE('1. Raw Data'!J17)),0) -> 5.89 | N17: ='1. Raw Data'!K17 -> 12 | O17: =IFERROR(IF(M17=0,0,(L17*(M17/100/12))/(1-(1+M17/100/12)^(-N17))),0) -> 12662.297 | P17: ='1. Raw Data'!L17 -> 72 | Q17: =TRIM('1. Raw Data'!M17) -> Premium
A18: ='1. Raw Data'!A18 -> TXN-100016 | B18: =IFERROR(DATEVALUE('1. Raw Data'!B18),"") -> 45632 | C18: =IFERROR(TEXT(B18,"mmm"),"") -> Dec | D18: =IFERROR("Q"&INT((MONTH(B18)-1)/3+1),"") -> Q4 | E18: =IFERROR(YEAR(B18),"") -> 2024 | F18: =PROPER(TRIM('1. Raw Data'!C18)) -> Uptown | G18: =TRIM('1. Raw Data'!D18) -> Fixed Deposit | H18: =TRIM('1. Raw Data'!E18) -> Deposits | I18: =TRIM('1. Raw Data'!F18) -> David Kim | J18: =PROPER(TRIM('1. Raw Data'!G18)) -> Active | K18: =TRIM('1. Raw Data'!H18) -> High | L18: =IFERROR(IF('1. Raw Data'!I18="",AVERAGE(IF('1. Raw Data'!I3:I402<>"",'1. Raw Data'!I3:I402)),VALUE('1. Raw Data'!I18)),0) -> 90279.87 | M18: =IFERROR(IF('1. Raw Data'!J18="",AVERAGE(IF('1. Raw Data'!J3:J402<>"",'1. Raw Data'!J3:J402)),VALUE('1. Raw Data'!J18)),0) -> 4.89 | N18: ='1. Raw Data'!K18 -> 180 | O18: =IFERROR(IF(M18=0,0,(L18*(M18/100/12))/(1-(1+M18/100/12)^(-N18))),0) -> 708.76501 | P18: ='1. Raw Data'!L18 -> 58 | Q18: =TRIM('1. Raw Data'!M18) -> Standard
A19: ='1. Raw Data'!A19 -> TXN-100017 | B19: =IFERROR(DATEVALUE('1. Raw Data'!B19),"") -> 45397 | C19: =IFERROR(TEXT(B19,"mmm"),"") -> Apr | D19: =IFERROR("Q"&INT((MONTH(B19)-1)/3+1),"") -> Q2 | E19: =IFERROR(YEAR(B19),"") -> 2024 | F19: =PROPER(TRIM('1. Raw Data'!C19)) -> Eastgate | G19: =TRIM('1. Raw Data'!D19) -> Fixed Deposit | H19: =TRIM('1. Raw Data'!E19) -> Deposits | I19: =TRIM('1. Raw Data'!F19) -> James Patel | J19: =PROPER(TRIM('1. Raw Data'!G19)) -> Active | K19: =TRIM('1. Raw Data'!H19) -> High | L19: =IFERROR(IF('1. Raw Data'!I19="",AVERAGE(IF('1. Raw Data'!I3:I402<>"",'1. Raw Data'!I3:I402)),VALUE('1. Raw Data'!I19)),0) -> 131032.14 | M19: =IFERROR(IF('1. Raw Data'!J19="",AVERAGE(IF('1. Raw Data'!J3:J402<>"",'1. Raw Data'!J3:J402)),VALUE('1. Raw Data'!J19)),0) -> 3.82 | N19: ='1. Raw Data'!K19 -> 180 | O19: =IFERROR(IF(M19=0,0,(L19*(M19/100/12))/(1-(1+M19/100/12)^(-N19))),0) -> 957.45204 | P19: ='1. Raw Data'!L19 -> 26 | Q19: =TRIM('1. Raw Data'!M19) -> Premium
A20: ='1. Raw Data'!A20 -> TXN-100018 | B20: =IFERROR(DATEVALUE('1. Raw Data'!B20),"") -> 45370 | C20: =IFERROR(TEXT(B20,"mmm"),"") -> Mar | D20: =IFERROR("Q"&INT((MONTH(B20)-1)/3+1),"") -> Q1 | E20: =IFERROR(YEAR(B20),"") -> 2024 | F20: =PROPER(TRIM('1. Raw Data'!C20)) -> Downtown | G20: =TRIM('1. Raw Data'!D20) -> Auto Loan | H20: =TRIM('1. Raw Data'!E20) -> Loans | I20: =TRIM('1. Raw Data'!F20) -> David Kim | J20: =PROPER(TRIM('1. Raw Data'!G20)) -> Active | K20: =TRIM('1. Raw Data'!H20) -> Low | L20: =IFERROR(IF('1. Raw Data'!I20="",AVERAGE(IF('1. Raw Data'!I3:I402<>"",'1. Raw Data'!I3:I402)),VALUE('1. Raw Data'!I20)),0) -> 230038.56 | M20: =IFERROR(IF('1. Raw Data'!J20="",AVERAGE(IF('1. Raw Data'!J3:J402<>"",'1. Raw Data'!J3:J402)),VALUE('1. Raw Data'!J20)),0) -> 7.07 | N20: ='1. Raw Data'!K20 -> 6 | O20: =IFERROR(IF(M20=0,0,(L20*(M20/100/12))/(1-(1+M20/100/12)^(-N20))),0) -> 39134.228 | P20: ='1. Raw Data'!L20 -> 43 | Q20: =TRIM('1. Raw Data'!M20) -> Premium
A21: ='1. Raw Data'!A21 -> TXN-100019 | B21: =IFERROR(DATEVALUE('1. Raw Data'!B21),"") -> 45338 | C21: =IFERROR(TEXT(B21,"mmm"),"") -> Feb | D21: =IFERROR("Q"&INT((MONTH(B21)-1)/3+1),"") -> Q1 | E21: =IFERROR(YEAR(B21),"") -> 2024 | F21: =PROPER(TRIM('1. Raw Data'!C21)) -> Downtown | G21: =TRIM('1. Raw Data'!D21) -> Business Loan | H21: =TRIM('1. Raw Data'!E21) -> Loans | I21: =TRIM('1. Raw Data'!F21) -> James Patel | J21: =PROPER(TRIM('1. Raw Data'!G21)) -> Pending | K21: =TRIM('1. Raw Data'!H21) -> Low | L21: =IFERROR(IF('1. Raw Data'!I21="",AVERAGE(IF('1. Raw Data'!I3:I402<>"",'1. Raw Data'!I3:I402)),VALUE('1. Raw Data'!I21)),0) -> 43373.31 | M21: =IFERROR(IF('1. Raw Data'!J21="",AVERAGE(IF('1. Raw Data'!J3:J402<>"",'1. Raw Data'!J3:J402)),VALUE('1. Raw Data'!J21)),0) -> 5.67 | N21: ='1. Raw Data'!K21 -> 60 | O21: =IFERROR(IF(M21=0,0,(L21*(M21/100/12))/(1-(1+M21/100/12)^(-N21))),0) -> 831.88828 | P21: ='1. Raw Data'!L21 -> 26 | Q21: =TRIM('1. Raw Data'!M21) -> Standard
A22: ='1. Raw Data'!A22 -> TXN-100020 | B22: =IFERROR(DATEVALUE('1. Raw Data'!B22),"") -> 45356 | C22: =IFERROR(TEXT(B22,"mmm"),"") -> Mar | D22: =IFERROR("Q"&INT((MONTH(B22)-1)/3+1),"") -> Q1 | E22: =IFERROR(YEAR(B22),"") -> 2024 | F22: =PROPER(TRIM('1. Raw Data'!C22)) -> Northpark | G22: =TRIM('1. Raw Data'!D22) -> Savings Account | H22: =TRIM('1. Raw Data'!E22) -> Deposits | I22: =TRIM('1. Raw Data'!F22) -> Sarah Chen | J22: =PROPER(TRIM('1. Raw Data'!G22)) -> Inactive | K22: =TRIM('1. Raw Data'!H22) -> Low | L22: =IFERROR(IF('1. Raw Data'!I22="",AVERAGE(IF('1. Raw Data'!I3:I402<>"",'1. Raw Data'!I3:I402)),VALUE('1. Raw Data'!I22)),0) -> 136558.12 | M22: =IFERROR(IF('1. Raw Data'!J22="",AVERAGE(IF('1. Raw Data'!J3:J402<>"",'1. Raw Data'!J3:J402)),VALUE('1. Raw Data'!J22)),0) -> 2.88 | N22: ='1. Raw Data'!K22 -> 240 | O22: =IFERROR(IF(M22=0,0,(L22*(M22/100/12))/(1-(1+M22/100/12)^(-N22))),0) -> 749.17108 | P22: ='1. Raw Data'!L22 -> 63 | Q22: =TRIM('1. Raw Data'!M22) -> Premium
A23: ='1. Raw Data'!A23 -> TXN-100021 | B23: =IFERROR(DATEVALUE('1. Raw Data'!B23),"") -> 45469 | C23: =IFERROR(TEXT(B23,"mmm"),"") -> Jun | D23: =IFERROR("Q"&INT((MONTH(B23)-1)/3+1),"") -> Q2 | E23: =IFERROR(YEAR(B23),"") -> 2024 | F23: =PROPER(TRIM('1. Raw Data'!C23)) -> Northpark | G23: =TRIM('1. Raw Data'!D23) -> Personal Loan | H23: =TRIM('1. Raw Data'!E23) -> Loans | I23: =TRIM('1. Raw Data'!F23) -> Maria Lopez | J23: =PROPER(TRIM('1. Raw Data'!G23)) -> Pending | K23: =TRIM('1. Raw Data'!H23) -> Low | L23: =IFERROR(IF('1. Raw Data'!I23="",AVERAGE(IF('1. Raw Data'!I3:I402<>"",'1. Raw Data'!I3:I402)),VALUE('1. Raw Data'!I23)),0) -> 156452.99 | M23: =IFERROR(IF('1. Raw Data'!J23="",AVERAGE(IF('1. Raw Data'!J3:J402<>"",'1. Raw Data'!J3:J402)),VALUE('1. Raw Data'!J23)),0) -> 4.66 | N23: ='1. Raw Data'!K23 -> 24 | O23: =IFERROR(IF(M23=0,0,(L23*(M23/100/12))/(1-(1+M23/100/12)^(-N23))),0) -> 6840.0123 | P23: ='1. Raw Data'!L23 -> 69 | Q23: =TRIM('1. Raw Data'!M23) -> Premium
A24: ='1. Raw Data'!A24 -> TXN-100022 | B24: =IFERROR(DATEVALUE('1. Raw Data'!B24),"") -> 45401 | C24: =IFERROR(TEXT(B24,"mmm"),"") -> Apr | D24: =IFERROR("Q"&INT((MONTH(B24)-1)/3+1),"") -> Q2 | E24: =IFERROR(YEAR(B24),"") -> 2024 | F24: =PROPER(TRIM('1. Raw Data'!C24)) -> Downtown | G24: =TRIM('1. Raw Data'!D24) -> Mortgage | H24: =TRIM('1. Raw Data'!E24) -> Loans | I24: =TRIM('1. Raw Data'!F24) -> David Kim | J24: =PROPER(TRIM('1. Raw Data'!G24)) -> Inactive | K24: =TRIM('1. Raw Data'!H24) -> Low | L24: =IFERROR(IF('1. Raw Data'!I24="",AVERAGE(IF('1. Raw Data'!I3:I402<>"",'1. Raw Data'!I3:I402)),VALUE('1. Raw Data'!I24)),0) -> 111240.32 | M24: =IFERROR(IF('1. Raw Data'!J24="",AVERAGE(IF('1. Raw Data'!J3:J402<>"",'1. Raw Data'!J3:J402)),VALUE('1. Raw Data'!J24)),0) -> 11.62 | N24: ='1. Raw Data'!K24 -> 12 | O24: =IFERROR(IF(M24=0,0,(L24*(M24/100/12))/(1-(1+M24/100/12)^(-N24))),0) -> 9863.8037 | P24: ='1. Raw Data'!L24 -> 74 | Q24: =TRIM('1. Raw Data'!M24) -> Premium
A25: ='1. Raw Data'!A25 -> TXN-100023 | B25: =IFERROR(DATEVALUE('1. Raw Data'!B25),"") -> 45474 | C25: =IFERROR(TEXT(B25,"mmm"),"") -> Jul | D25: =IFERROR("Q"&INT((MONTH(B25)-1)/3+1),"") -> Q3 | E25: =IFERROR(YEAR(B25),"") -> 2024 | F25: =PROPER(TRIM('1. Raw Data'!C25)) -> Westside | G25: =TRIM('1. Raw Data'!D25) -> Auto Loan | H25: =TRIM('1. Raw Data'!E25) -> Loans | I25: =TRIM('1. Raw Data'!F25) -> Rachel Moore | J25: =PROPER(TRIM('1. Raw Data'!G25)) -> Active | K25: =TRIM('1. Raw Data'!H25) -> High | L25: =IFERROR(IF('1. Raw Data'!I25="",AVERAGE(IF('1. Raw Data'!I3:I402<>"",'1. Raw Data'!I3:I402)),VALUE('1. Raw Data'!I25)),0) -> 75509.09 | M25: =IFERROR(IF('1. Raw Data'!J25="",AVERAGE(IF('1. Raw Data'!J3:J402<>"",'1. Raw Data'!J3:J402)),VALUE('1. Raw Data'!J25)),0) -> 4.33 | N25: ='1. Raw Data'!K25 -> 6 | O25: =IFERROR(IF(M25=0,0,(L25*(M25/100/12))/(1-(1+M25/100/12)^(-N25))),0) -> 12744.262 | P25: ='1. Raw Data'!L25 -> 40 | Q25: =TRIM('1. Raw Data'!M25) -> Standard
A26: ='1. Raw Data'!A26 -> TXN-100024 | B26: =IFERROR(DATEVALUE('1. Raw Data'!B26),"") -> 45607 | C26: =IFERROR(TEXT(B26,"mmm"),"") -> Nov | D26: =IFERROR("Q"&INT((MONTH(B26)-1)/3+1),"") -> Q4 | E26: =IFERROR(YEAR(B26),"") -> 2024 | F26: =PROPER(TRIM('1. Raw Data'!C26)) -> Downtown | G26: =TRIM('1. Raw Data'!D26) -> Checking Account | H26: =TRIM('1. Raw Data'!E26) -> Deposits | I26: =TRIM('1. Raw Data'!F26) -> Maria Lopez | J26: =PROPER(TRIM('1. Raw Data'!G26)) -> Active | K26: =TRIM('1. Raw Data'!H26) -> High | L26: =IFERROR(IF('1. Raw Data'!I26="",AVERAGE(IF('1. Raw Data'!I3:I402<>"",'1. Raw Data'!I3:I402)),VALUE('1. Raw Data'!I26)),0) -> 211721.92 | M26: =IFERROR(IF('1. Raw Data'!J26="",AVERAGE(IF('1. Raw Data'!J3:J402<>"",'1. Raw Data'!J3:J402)),VALUE('1. Raw Data'!J26)),0) -> 10.14 | N26: ='1. Raw Data'!K26 -> 6 | O26: =IFERROR(IF(M26=0,0,(L26*(M26/100/12))/(1-(1+M26/100/12)^(-N26))),0) -> 36337.917 | P26: ='1. Raw Data'!L26 -> 46 | Q26: =TRIM('1. Raw Data'!M26) -> Premium
A27: ='1. Raw Data'!A27 -> TXN-100025 | B27: =IFERROR(DATEVALUE('1. Raw Data'!B27),"") -> 45651 | C27: =IFERROR(TEXT(B27,"mmm"),"") -> Dec | D27: =IFERROR("Q"&INT((MONTH(B27)-1)/3+1),"") -> Q4 | E27: =IFERROR(YEAR(B27),"") -> 2024 | F27: =PROPER(TRIM('1. Raw Data'!C27)) -> Downtown | G27: =TRIM('1. Raw Data'!D27) -> Credit Card | H27: =TRIM('1. Raw Data'!E27) -> Cards | I27: =TRIM('1. Raw Data'!F27) -> David Kim | J27: =PROPER(TRIM('1. Raw Data'!G27)) -> Active | K27: =TRIM('1. Raw Data'!H27) -> High | L27: =IFERROR(IF('1. Raw Data'!I27="",AVERAGE(IF('1. Raw Data'!I3:I402<>"",'1. Raw Data'!I3:I402)),VALUE('1. Raw Data'!I27)),0) -> 57343.43 | M27: =IFERROR(IF('1. Raw Data'!J27="",AVERAGE(IF('1. Raw Data'!J3:J402<>"",'1. Raw Data'!J3:J402)),VALUE('1. Raw Data'!J27)),0) -> 8.53 | N27: ='1. Raw Data'!K27 -> 6 | O27: =IFERROR(IF(M27=0,0,(L27*(M27/100/12))/(1-(1+M27/100/12)^(-N27))),0) -> 9796.4179 | P27: ='1. Raw Data'!L27 -> 35 | Q27: =TRIM('1. Raw Data'!M27) -> Standard
A28: ='1. Raw Data'!A28 -> TXN-100026 | B28: =IFERROR(DATEVALUE('1. Raw Data'!B28),"") -> 45606 | C28: =IFERROR(TEXT(B28,"mmm"),"") -> Nov | D28: =IFERROR("Q"&INT((MONTH(B28)-1)/3+1),"") -> Q4 | E28: =IFERROR(YEAR(B28),"") -> 2024 | F28: =PROPER(TRIM('1. Raw Data'!C28)) -> Downtown | G28: =TRIM('1. Raw Data'!D28) -> Checking Account | H28: =TRIM('1. Raw Data'!E28) -> Deposits | I28: =TRIM('1. Raw Data'!F28) -> James Patel | J28: =PROPER(TRIM('1. Raw Data'!G28)) -> Active | K28: =TRIM('1. Raw Data'!H28) -> Low | L28: =IFERROR(IF('1. Raw Data'!I28="",AVERAGE(IF('1. Raw Data'!I3:I402<>"",'1. Raw Data'!I3:I402)),VALUE('1. Raw Data'!I28)),0) -> 15787.27 | M28: =IFERROR(IF('1. Raw Data'!J28="",AVERAGE(IF('1. Raw Data'!J3:J402<>"",'1. Raw Data'!J3:J402)),VALUE('1. Raw Data'!J28)),0) -> 12.62 | N28: ='1. Raw Data'!K28 -> 24 | O28: =IFERROR(IF(M28=0,0,(L28*(M28/100/12))/(1-(1+M28/100/12)^(-N28))),0) -> 747.74083 | P28: ='1. Raw Data'!L28 -> 59 | Q28: =TRIM('1. Raw Data'!M28) -> Basic
A29: ='1. Raw Data'!A29 -> TXN-100027 | B29: =IFERROR(DATEVALUE('1. Raw Data'!B29),"") -> 45393 | C29: =IFERROR(TEXT(B29,"mmm"),"") -> Apr | D29: =IFERROR("Q"&INT((MONTH(B29)-1)/3+1),"") -> Q2 | E29: =IFERROR(YEAR(B29),"") -> 2024 | F29: =PROPER(TRIM('1. Raw Data'!C29)) -> Eastgate | G29: =TRIM('1. Raw Data'!D29) -> Fixed Deposit | H29: =TRIM('1. Raw Data'!E29) -> Deposits | I29: =TRIM('1. Raw Data'!F29) -> Sarah Chen | J29: =PROPER(TRIM('1. Raw Data'!G29)) -> Active | K29: =TRIM('1. Raw Data'!H29) -> High | L29: =IFERROR(IF('1. Raw Data'!I29="",AVERAGE(IF('1. Raw Data'!I3:I402<>"",'1. Raw Data'!I3:I402)),VALUE('1. Raw Data'!I29)),0) -> 108949.17 | M29: =IFERROR(IF('1. Raw Data'!J29="",AVERAGE(IF('1. Raw Data'!J3:J402<>"",'1. Raw Data'!J3:J402)),VALUE('1. Raw Data'!J29)),0) -> 8 | N29: ='1. Raw Data'!K29 -> 360 | O29: =IFERROR(IF(M29=0,0,(L29*(M29/100/12))/(1-(1+M29/100/12)^(-N29))),0) -> 799.43041 | P29: ='1. Raw Data'!L29 -> 27 | Q29: =TRIM('1. Raw Data'!M29) -> Premium
A30: ='1. Raw Data'!A30 -> TXN-100028 | B30: =IFERROR(DATEVALUE('1. Raw Data'!B30),"") -> 45367 | C30: =IFERROR(TEXT(B30,"mmm"),"") -> Mar | D30: =IFERROR("Q"&INT((MONTH(B30)-1)/3+1),"") -> Q1 | E30: =IFERROR(YEAR(B30),"") -> 2024 | F30: =PROPER(TRIM('1. Raw Data'!C30)) -> Downtown | G30: =TRIM('1. Raw Data'!D30) -> Business Loan | H30: =TRIM('1. Raw Data'!E30) -> Loans | I30: =TRIM('1. Raw Data'!F30) -> Rachel Moore | J30: =PROPER(TRIM('1. Raw Data'!G30)) -> Active | K30: =TRIM('1. Raw Data'!H30) -> Low | L30: =IFERROR(IF('1. Raw Data'!I30="",AVERAGE(IF('1. Raw Data'!I3:I402<>"",'1. Raw Data'!I3:I402)),VALUE('1. Raw Data'!I30)),0) -> 184668.95 | M30: =IFERROR(IF('1. Raw Data'!J30="",AVERAGE(IF('1. Raw Data'!J3:J402<>"",'1. Raw Data'!J3:J402)),VALUE('1. Raw Data'!J30)),0) -> 5.36 | N30: ='1. Raw Data'!K30 -> 48 | O30: =IFERROR(IF(M30=0,0,(L30*(M30/100/12))/(1-(1+M30/100/12)^(-N30))),0) -> 4282.9764 | P30: ='1. Raw Data'!L30 -> 32 | Q30: =TRIM('1. Raw Data'!M30) -> Premium
A31: ='1. Raw Data'!A31 -> TXN-100029 | B31: =IFERROR(DATEVALUE('1. Raw Data'!B31),"") -> 45404 | C31: =IFERROR(TEXT(B31,"mmm"),"") -> Apr | D31: =IFERROR("Q"&INT((MONTH(B31)-1)/3+1),"") -> Q2 | E31: =IFERROR(YEAR(B31),"") -> 2024 | F31: =PROPER(TRIM('1. Raw Data'!C31)) -> Northpark | G31: =TRIM('1. Raw Data'!D31) -> Savings Account | H31: =TRIM('1. Raw Data'!E31) -> Deposits | I31: =TRIM('1. Raw Data'!F31) -> James Patel | J31: =PROPER(TRIM('1. Raw Data'!G31)) -> Active | K31: =TRIM('1. Raw Data'!H31) -> High | L31: =IFERROR(IF('1. Raw Data'!I31="",AVERAGE(IF('1. Raw Data'!I3:I402<>"",'1. Raw Data'!I3:I402)),VALUE('1. Raw Data'!I31)),0) -> 176395.17 | M31: =IFERROR(IF('1. Raw Data'!J31="",AVERAGE(IF('1. Raw Data'!J3:J402<>"",'1. Raw Data'!J3:J402)),VALUE('1. Raw Data'!J31)),0) -> 7.05 | N31: ='1. Raw Data'!K31 -> 240 | O31: =IFERROR(IF(M31=0,0,(L31*(M31/100/12))/(1-(1+M31/100/12)^(-N31))),0) -> 1372.889 | P31: ='1. Raw Data'!L31 -> 26 | Q31: =TRIM('1. Raw Data'!M31) -> Premium
A32: ='1. Raw Data'!A32 -> TXN-100030 | B32: =IFERROR(DATEVALUE('1. Raw Data'!B32),"") -> 45450 | C32: =IFERROR(TEXT(B32,"mmm"),"") -> Jun | D32: =IFERROR("Q"&INT((MONTH(B32)-1)/3+1),"") -> Q2 | E32: =IFERROR(YEAR(B32),"") -> 2024 | F32: =PROPER(TRIM('1. Raw Data'!C32)) -> Downtown | G32: =TRIM('1. Raw Data'!D32) -> Checking Account | H32: =TRIM('1. Raw Data'!E32) -> Deposits | I32: =TRIM('1. Raw Data'!F32) -> Sarah Chen | J32: =PROPER(TRIM('1. Raw Data'!G32)) -> Active | K32: =TRIM('1. Raw Data'!H32) -> Low | L32: =IFERROR(IF('1. Raw Data'!I32="",AVERAGE(IF('1. Raw Data'!I3:I402<>"",'1. Raw Data'!I3:I402)),VALUE('1. Raw Data'!I32)),0) -> 0 | M32: =IFERROR(IF('1. Raw Data'!J32="",AVERAGE(IF('1. Raw Data'!J3:J402<>"",'1. Raw Data'!J3:J402)),VALUE('1. Raw Data'!J32)),0) -> 10.12 | N32: ='1. Raw Data'!K32 -> 24 | O32: =IFERROR(IF(M32=0,0,(L32*(M32/100/12))/(1-(1+M32/100/12)^(-N32))),0) -> 0 | P32: ='1. Raw Data'!L32 -> 39 | Q32: =TRIM('1. Raw Data'!M32) -> Premium
A33: ='1. Raw Data'!A33 -> TXN-100031 | B33: =IFERROR(DATEVALUE('1. Raw Data'!B33),"") -> 45478 | C33: =IFERROR(TEXT(B33,"mmm"),"") -> Jul | D33: =IFERROR("Q"&INT((MONTH(B33)-1)/3+1),"") -> Q3 | E33: =IFERROR(YEAR(B33),"") -> 2024 | F33: =PROPER(TRIM('1. Raw Data'!C33)) -> Uptown | G33: =TRIM('1. Raw Data'!D33) -> Auto Loan | H33: =TRIM('1. Raw Data'!E33) -> Loans | I33: =TRIM('1. Raw Data'!F33) -> Sarah Chen | J33: =PROPER(TRIM('1. Raw Data'!G33)) -> Active | K33: =TRIM('1. Raw Data'!H33) -> Medium | L33: =IFERROR(IF('1. Raw Data'!I33="",AVERAGE(IF('1. Raw Data'!I3:I402<>"",'1. Raw Data'!I3:I402)),VALUE('1. Raw Data'!I33)),0) -> 174300.23 | M33: =IFERROR(IF('1. Raw Data'!J33="",AVERAGE(IF('1. Raw Data'!J3:J402<>"",'1. Raw Data'!J3:J402)),VALUE('1. Raw Data'!J33)),0) -> 8.6 | N33: ='1. Raw Data'!K33 -> 36 | O33: =IFERROR(IF(M33=0,0,(L33*(M33/100/12))/(1-(1+M33/100/12)^(-N33))),0) -> 5510.3091 | P33: ='1. Raw Data'!L33 -> 50 | Q33: =TRIM('1. Raw Data'!M33) -> Premium
A34: ='1. Raw Data'!A34 -> TXN-100032 | B34: =IFERROR(DATEVALUE('1. Raw Data'!B34),"") -> 45481 | C34: =IFERROR(TEXT(B34,"mmm"),"") -> Jul | D34: =IFERROR("Q"&INT((MONTH(B34)-1)/3+1),"") -> Q3 | E34: =IFERROR(YEAR(B34),"") -> 2024 | F34: =PROPER(TRIM('1. Raw Data'!C34)) -> Downtown | G34: =TRIM('1. Raw Data'!D34) -> Business Loan | H34: =TRIM('1. Raw Data'!E34) -> Loans | I34: =TRIM('1. Raw Data'!F34) -> Sarah Chen | J34: =PROPER(TRIM('1. Raw Data'!G34)) -> Active | K34: =TRIM('1. Raw Data'!H34) -> Medium | L34: =IFERROR(IF('1. Raw Data'!I34="",AVERAGE(IF('1. Raw Data'!I3:I402<>"",'1. Raw Data'!I3:I402)),VALUE('1. Raw Data'!I34)),0) -> 134809.56 | M34: =IFERROR(IF('1. Raw Data'!J34="",AVERAGE(IF('1. Raw Data'!J3:J402<>"",'1. Raw Data'!J3:J402)),VALUE('1. Raw Data'!J34)),0) -> 11.47 | N34: ='1. Raw Data'!K34 -> 6 | O34: =IFERROR(IF(M34=0,0,(L34*(M34/100/12))/(1-(1+M34/100/12)^(-N34))),0) -> 23225.875 | P34: ='1. Raw Data'!L34 -> 23 | Q34: =TRIM('1. Raw Data'!M34) -> Premium
A35: ='1. Raw Data'!A35 -> TXN-100033 | B35: =IFERROR(DATEVALUE('1. Raw Data'!B35),"") -> 45345 | C35: =IFERROR(TEXT(B35,"mmm"),"") -> Feb | D35: =IFERROR("Q"&INT((MONTH(B35)-1)/3+1),"") -> Q1 | E35: =IFERROR(YEAR(B35),"") -> 2024 | F35: =PROPER(TRIM('1. Raw Data'!C35)) -> Downtown | G35: =TRIM('1. Raw Data'!D35) -> Checking Account | H35: =TRIM('1. Raw Data'!E35) -> Deposits | I35: =TRIM('1. Raw Data'!F35) -> David Kim | J35: =PROPER(TRIM('1. Raw Data'!G35)) -> Active | K35: =TRIM('1. Raw Data'!H35) -> Medium | L35: =IFERROR(IF('1. Raw Data'!I35="",AVERAGE(IF('1. Raw Data'!I3:I402<>"",'1. Raw Data'!I3:I402)),VALUE('1. Raw Data'!I35)),0) -> 211082.87 | M35: =IFERROR(IF('1. Raw Data'!J35="",AVERAGE(IF('1. Raw Data'!J3:J402<>"",'1. Raw Data'!J3:J402)),VALUE('1. Raw Data'!J35)),0) -> 10.86 | N35: ='1. Raw Data'!K35 -> 180 | O35: =IFERROR(IF(M35=0,0,(L35*(M35/100/12))/(1-(1+M35/100/12)^(-N35))),0) -> 2380.6375 | P35: ='1. Raw Data'!L35 -> 49 | Q35: =TRIM('1. Raw Data'!M35) -> Premium
A36: ='1. Raw Data'!A36 -> TXN-100034 | B36: =IFERROR(DATEVALUE('1. Raw Data'!B36),"") -> 45385 | C36: =IFERROR(TEXT(B36,"mmm"),"") -> Apr | D36: =IFERROR("Q"&INT((MONTH(B36)-1)/3+1),"") -> Q2 | E36: =IFERROR(YEAR(B36),"") -> 2024 | F36: =PROPER(TRIM('1. Raw Data'!C36)) -> Westside | G36: =TRIM('1. Raw Data'!D36) -> Auto Loan | H36: =TRIM('1. Raw Data'!E36) -> Loans | I36: =TRIM('1. Raw Data'!F36) -> Sarah Chen | J36: =PROPER(TRIM('1. Raw Data'!G36)) -> Active | K36: =TRIM('1. Raw Data'!H36) -> High | L36: =IFERROR(IF('1. Raw Data'!I36="",AVERAGE(IF('1. Raw Data'!I3:I402<>"",'1. Raw Data'!I3:I402)),VALUE('1. Raw Data'!I36)),0) -> 232615.16 | M36: =IFERROR(IF('1. Raw Data'!J36="",AVERAGE(IF('1. Raw Data'!J3:J402<>"",'1. Raw Data'!J3:J402)),VALUE('1. Raw Data'!J36)),0) -> 5.03 | N36: ='1. Raw Data'!K36 -> 60 | O36: =IFERROR(IF(M36=0,0,(L36*(M36/100/12))/(1-(1+M36/100/12)^(-N36))),0) -> 4392.9329 | P36: ='1. Raw Data'!L36 -> 61 | Q36: =TRIM('1. Raw Data'!M36) -> Premium
A37: ='1. Raw Data'!A37 -> TXN-100035 | B37: =IFERROR(DATEVALUE('1. Raw Data'!B37),"") -> 45635 | C37: =IFERROR(TEXT(B37,"mmm"),"") -> Dec | D37: =IFERROR("Q"&INT((MONTH(B37)-1)/3+1),"") -> Q4 | E37: =IFERROR(YEAR(B37),"") -> 2024 | F37: =PROPER(TRIM('1. Raw Data'!C37)) -> Eastgate | G37: =TRIM('1. Raw Data'!D37) -> Fixed Deposit | H37: =TRIM('1. Raw Data'!E37) -> Deposits | I37: =TRIM('1. Raw Data'!F37) -> Rachel Moore | J37: =PROPER(TRIM('1. Raw Data'!G37)) -> Active | K37: =TRIM('1. Raw Data'!H37) -> High | L37: =IFERROR(IF('1. Raw Data'!I37="",AVERAGE(IF('1. Raw Data'!I3:I402<>"",'1. Raw Data'!I3:I402)),VALUE('1. Raw Data'!I37)),0) -> 19870.29 | M37: =IFERROR(IF('1. Raw Data'!J37="",AVERAGE(IF('1. Raw Data'!J3:J402<>"",'1. Raw Data'!J3:J402)),VALUE('1. Raw Data'!J37)),0) -> 6.91 | N37: ='1. Raw Data'!K37 -> 6 | O37: =IFERROR(IF(M37=0,0,(L37*(M37/100/12))/(1-(1+M37/100/12)^(-N37))),0) -> 3378.7792 | P37: ='1. Raw Data'!L37 -> 40 | Q37: =TRIM('1. Raw Data'!M37) -> Basic
A38: ='1. Raw Data'!A38 -> TXN-100036 | B38: =IFERROR(DATEVALUE('1. Raw Data'!B38),"") -> 45332 | C38: =IFERROR(TEXT(B38,"mmm"),"") -> Feb | D38: =IFERROR("Q"&INT((MONTH(B38)-1)/3+1),"") -> Q1 | E38: =IFERROR(YEAR(B38),"") -> 2024 | F38: =PROPER(TRIM('1. Raw Data'!C38)) -> Westside | G38: =TRIM('1. Raw Data'!D38) -> Mortgage | H38: =TRIM('1. Raw Data'!E38) -> Loans | I38: =TRIM('1. Raw Data'!F38) -> Rachel Moore | J38: =PROPER(TRIM('1. Raw Data'!G38)) -> Inactive | K38: =TRIM('1. Raw Data'!H38) -> High | L38: =IFERROR(IF('1. Raw Data'!I38="",AVERAGE(IF('1. Raw Data'!I3:I402<>"",'1. Raw Data'!I3:I402)),VALUE('1. Raw Data'!I38)),0) -> 99894.86 | M38: =IFERROR(IF('1. Raw Data'!J38="",AVERAGE(IF('1. Raw Data'!J3:J402<>"",'1. Raw Data'!J3:J402)),VALUE('1. Raw Data'!J38)),0) -> 4.9 | N38: ='1. Raw Data'!K38 -> 360 | O38: =IFERROR(IF(M38=0,0,(L38*(M38/100/12))/(1-(1+M38/100/12)^(-N38))),0) -> 530.16871 | P38: ='1. Raw Data'!L38 -> 39 | Q38: =TRIM('1. Raw Data'!M38) -> Standard
A39: ='1. Raw Data'!A39 -> TXN-100037 | B39: =IFERROR(DATEVALUE('1. Raw Data'!B39),"") -> 45480 | C39: =IFERROR(TEXT(B39,"mmm"),"") -> Jul | D39: =IFERROR("Q"&INT((MONTH(B39)-1)/3+1),"") -> Q3 | E39: =IFERROR(YEAR(B39),"") -> 2024 | F39: =PROPER(TRIM('1. Raw Data'!C39)) -> Downtown | G39: =TRIM('1. Raw Data'!D39) -> Checking Account | H39: =TRIM('1. Raw Data'!E39) -> Deposits | I39: =TRIM('1. Raw Data'!F39) -> Rachel Moore | J39: =PROPER(TRIM('1. Raw Data'!G39)) -> Active | K39: =TRIM('1. Raw Data'!H39) -> Low | L39: =IFERROR(IF('1. Raw Data'!I39="",AVERAGE(IF('1. Raw Data'!I3:I402<>"",'1. Raw Data'!I3:I402)),VALUE('1. Raw Data'!I39)),0) -> 106129.92 | M39: =IFERROR(IF('1. Raw Data'!J39="",AVERAGE(IF('1. Raw Data'!J3:J402<>"",'1. Raw Data'!J3:J402)),VALUE('1. Raw Data'!J39)),0) -> 10.12 | N39: ='1. Raw Data'!K39 -> 360 | O39: =IFERROR(IF(M39=0,0,(L39*(M39/100/12))/(1-(1+M39/100/12)^(-N39))),0) -> 940.79086 | P39: ='1. Raw Data'!L39 -> 59 | Q39: =TRIM('1. Raw Data'!M39) -> Premium
A40: ='1. Raw Data'!A40 -> TXN-100038 | B40: =IFERROR(DATEVALUE('1. Raw Data'!B40),"") -> 45378 | C40: =IFERROR(TEXT(B40,"mmm"),"") -> Mar | D40: =IFERROR("Q"&INT((MONTH(B40)-1)/3+1),"") -> Q1 | E40: =IFERROR(YEAR(B40),"") -> 2024 | F40: =PROPER(TRIM('1. Raw Data'!C40)) -> Downtown | G40: =TRIM('1. Raw Data'!D40) -> Checking Account | H40: =TRIM('1. Raw Data'!E40) -> Deposits | I40: =TRIM('1. Raw Data'!F40) -> David Kim | J40: =PROPER(TRIM('1. Raw Data'!G40)) -> Pending | K40: =TRIM('1. Raw Data'!H40) -> Medium | L40: =IFERROR(IF('1. Raw Data'!I40="",AVERAGE(IF('1. Raw Data'!I3:I402<>"",'1. Raw Data'!I3:I402)),VALUE('1. Raw Data'!I40)),0) -> 34141.6 | M40: =IFERROR(IF('1. Raw Data'!J40="",AVERAGE(IF('1. Raw Data'!J3:J402<>"",'1. Raw Data'!J3:J402)),VALUE('1. Raw Data'!J40)),0) -> 11.4 | N40: ='1. Raw Data'!K40 -> 48 | O40: =IFERROR(IF(M40=0,0,(L40*(M40/100/12))/(1-(1+M40/100/12)^(-N40))),0) -> 889.05424 | P40: ='1. Raw Data'!L40 -> 33 | Q40: =TRIM('1. Raw Data'!M40) -> Standard
...

Sheet 3. Analysis
A1: FINANCIAL ANALYSIS — Key Metrics & Breakdowns
A3: 📌 KEY PERFORMANCE INDICATORS
B4: Total Portfolio Value | F4: Total Transactions | K4: Average Loan Amount | O4: Average Interest Rate
B5: =SUMIF('2. Clean Data'!J3:J402,"Active",'2. Clean Data'!L3:L402) -> 35627697 | F5: =COUNTA('2. Clean Data'!A3:A402) -> 400 | K5: =AVERAGEIF('2. Clean Data'!H3:H402,"Loans",'2. Clean Data'!L3:L402) -> 114962.51 | O5: =AVERAGE('2. Clean Data'!M3:M402) -> 8.069775
B8: 📊 A. Portfolio Volume by Branch | K8: 📊 B. Portfolio by Product Category
B9: Branch | C9: Total Amount ($) | D9: # Transactions | E9: Avg Amount ($) | F9: Share (%) | K9: Category | L9: Total Amount ($) | M9: # Deals | N9: Avg Rate (%) | O9: Avg Term (mo) | P9: Share (%)
B10: Downtown | C10: =SUMIF('2. Clean Data'!F3:F402,B10,'2. Clean Data'!L3:L402) -> 9100452.3 | D10: =COUNTIF('2. Clean Data'!F3:F402,B10) -> 82 | E10: =IFERROR(C10/D10,0) -> 110981.13 | F10: =IFERROR(C10/SUM(C10:C14),0) -> 0.18812005 | K10: Deposits | L10: =SUMIF('2. Clean Data'!H3:H402,K10,'2. Clean Data'!L3:L402) -> 18786959 | M10: =COUNTIF('2. Clean Data'!H3:H402,K10) -> 145 | N10: =IFERROR(AVERAGEIF('2. Clean Data'!H3:H402,K10,'2. Clean Data'!M3:M402),0) -> 8.0493103 | O10: =IFERROR(AVERAGEIF('2. Clean Data'!H3:H402,K10,'2. Clean Data'!N3:N402),0) -> 104.97931 | P10: =IFERROR(L10/SUM(L10:L12),0) -> 0.38835472
B11: Uptown | C11: =SUMIF('2. Clean Data'!F3:F402,B11,'2. Clean Data'!L3:L402) -> 8389873.6 | D11: =COUNTIF('2. Clean Data'!F3:F402,B11) -> 69 | E11: =IFERROR(C11/D11,0) -> 121592.37 | F11: =IFERROR(C11/SUM(C10:C14),0) -> 0.17343132 | K11: Loans | L11: =SUMIF('2. Clean Data'!H3:H402,K11,'2. Clean Data'!L3:L402) -> 22992503 | M11: =COUNTIF('2. Clean Data'!H3:H402,K11) -> 200 | N11: =IFERROR(AVERAGEIF('2. Clean Data'!H3:H402,K11,'2. Clean Data'!M3:M402),0) -> 8.1814 | O11: =IFERROR(AVERAGEIF('2. Clean Data'!H3:H402,K11,'2. Clean Data'!N3:N402),0) -> 112.23 | P11: =IFERROR(L11/SUM(L10:L12),0) -> 0.47528965
B12: Westside | C12: =SUMIF('2. Clean Data'!F3:F402,B12,'2. Clean Data'!L3:L402) -> 9999752.6 | D12: =COUNTIF('2. Clean Data'!F3:F402,B12) -> 83 | E12: =IFERROR(C12/D12,0) -> 120478.95 | F12: =IFERROR(C12/SUM(C10:C14),0) -> 0.20670994 | K12: Cards | L12: =SUMIF('2. Clean Data'!H3:H402,K12,'2. Clean Data'!L3:L402) -> 6596308.7 | M12: =COUNTIF('2. Clean Data'!H3:H402,K12) -> 55 | N12: =IFERROR(AVERAGEIF('2. Clean Data'!H3:H402,K12,'2. Clean Data'!M3:M402),0) -> 7.7178182 | O12: =IFERROR(AVERAGEIF('2. Clean Data'!H3:H402,K12,'2. Clean Data'!N3:N402),0) -> 116.07273 | P12: =IFERROR(L12/SUM(L10:L12),0) -> 0.13635563
B13: Eastgate | C13: =SUMIF('2. Clean Data'!F3:F402,B13,'2. Clean Data'!L3:L402) -> 11233972 | D13: =COUNTIF('2. Clean Data'!F3:F402,B13) -> 94 | E13: =IFERROR(C13/D13,0) -> 119510.34 | F13: =IFERROR(C13/SUM(C10:C14),0) -> 0.23222311
B14: Northpark | C14: =SUMIF('2. Clean Data'!F3:F402,B14,'2. Clean Data'!L3:L402) -> 9651719.8 | D14: =COUNTIF('2. Clean Data'!F3:F402,B14) -> 72 | E14: =IFERROR(C14/D14,0) -> 134051.66 | F14: =IFERROR(C14/SUM(C10:C14),0) -> 0.19951558
B15: TOTAL | C15: =SUM(C10:C14) -> 48375770 | D15: =SUM(D10:D14) -> 400 | E15: =IFERROR(C15/D15,0) -> 120939.43 | F15: =SUM(F10:F14) -> 1
B18: 📅 C. Monthly Transaction Volume (2024) | K18: ⚠️ D. Portfolio by Risk Level
B19: Month | C19: Total Amount ($) | D19: # Transactions | E19: Avg Amount ($) | F19: MoM Growth (%) | K19: Risk Level | L19: Total Amount ($) | M19: # Accounts | N19: Avg Amount ($) | O19: % Portfolio
B20: Jan | C20: =SUMIF('2. Clean Data'!C3:C402,B20,'2. Clean Data'!L3:L402) -> 3822198.3 | D20: =COUNTIF('2. Clean Data'!C3:C402,B20) -> 33 | E20: =IFERROR(C20/D20,0) -> 115824.19 | F20: N/A | K20: Low | L20: =SUMIF('2. Clean Data'!K3:K402,K20,'2. Clean Data'!L3:L402) -> 17532903 | M20: =COUNTIF('2. Clean Data'!K3:K402,K20) -> 145 | N20: =IFERROR(L20/M20,0) -> 120916.57 | O20: =IFERROR(L20/SUM(L20:L22),0) -> 0.36243149
B21: Feb | C21: =SUMIF('2. Clean Data'!C3:C402,B21,'2. Clean Data'!L3:L402) -> 4373262.5 | D21: =COUNTIF('2. Clean Data'!C3:C402,B21) -> 39 | E21: =IFERROR(C21/D21,0) -> 112134.94 | F21: =IFERROR((C21-C20)/C20,0) -> 0.14417468 | K21: Medium | L21: =SUMIF('2. Clean Data'!K3:K402,K21,'2. Clean Data'!L3:L402) -> 18209026 | M21: =COUNTIF('2. Clean Data'!K3:K402,K21) -> 150 | N21: =IFERROR(L21/M21,0) -> 121393.51 | O21: =IFERROR(L21/SUM(L20:L22),0) -> 0.37640798
B22: Mar | C22: =SUMIF('2. Clean Data'!C3:C402,B22,'2. Clean Data'!L3:L402) -> 3887528.8 | D22: =COUNTIF('2. Clean Data'!C3:C402,B22) -> 34 | E22: =IFERROR(C22/D22,0) -> 114339.08 | F22: =IFERROR((C22-C21)/C21,0) -> -0.11106896 | K22: High | L22: =SUMIF('2. Clean Data'!K3:K402,K22,'2. Clean Data'!L3:L402) -> 12633842 | M22: =COUNTIF('2. Clean Data'!K3:K402,K22) -> 105 | N22: =IFERROR(L22/M22,0) -> 120322.3 | O22: =IFERROR(L22/SUM(L20:L22),0) -> 0.26116053
B23: Apr | C23: =SUMIF('2. Clean Data'!C3:C402,B23,'2. Clean Data'!L3:L402) -> 5167423.5 | D23: =COUNTIF('2. Clean Data'!C3:C402,B23) -> 44 | E23: =IFERROR(C23/D23,0) -> 117441.44 | F23: =IFERROR((C23-C22)/C22,0) -> 0.32923092
B24: May | C24: =SUMIF('2. Clean Data'!C3:C402,B24,'2. Clean Data'!L3:L402) -> 3562507.4 | D24: =COUNTIF('2. Clean Data'!C3:C402,B24) -> 29 | E24: =IFERROR(C24/D24,0) -> 122845.08 | F24: =IFERROR((C24-C23)/C23,0) -> -0.31058343
B25: Jun | C25: =SUMIF('2. Clean Data'!C3:C402,B25,'2. Clean Data'!L3:L402) -> 3995084.7 | D25: =COUNTIF('2. Clean Data'!C3:C402,B25) -> 31 | E25: =IFERROR(C25/D25,0) -> 128873.7 | F25: =IFERROR((C25-C24)/C24,0) -> 0.12142495
B26: Jul | C26: =SUMIF('2. Clean Data'!C3:C402,B26,'2. Clean Data'!L3:L402) -> 4022045.3 | D26: =COUNTIF('2. Clean Data'!C3:C402,B26) -> 33 | E26: =IFERROR(C26/D26,0) -> 121880.16 | F26: =IFERROR((C26-C25)/C25,0) -> 0.0067484326
B27: Aug | C27: =SUMIF('2. Clean Data'!C3:C402,B27,'2. Clean Data'!L3:L402) -> 4127197.2 | D27: =COUNTIF('2. Clean Data'!C3:C402,B27) -> 31 | E27: =IFERROR(C27/D27,0) -> 133135.39 | F27: =IFERROR((C27-C26)/C26,0) -> 0.026143885
B28: Sep | C28: =SUMIF('2. Clean Data'!C3:C402,B28,'2. Clean Data'!L3:L402) -> 4245862.2 | D28: =COUNTIF('2. Clean Data'!C3:C402,B28) -> 33 | E28: =IFERROR(C28/D28,0) -> 128662.49 | F28: =IFERROR((C28-C27)/C27,0) -> 0.028751973
B29: Oct | C29: =SUMIF('2. Clean Data'!C3:C402,B29,'2. Clean Data'!L3:L402) -> 3266373.7 | D29: =COUNTIF('2. Clean Data'!C3:C402,B29) -> 25 | E29: =IFERROR(C29/D29,0) -> 130654.95 | F29: =IFERROR((C29-C28)/C28,0) -> -0.23069248
B30: Nov | C30: =SUMIF('2. Clean Data'!C3:C402,B30,'2. Clean Data'!L3:L402) -> 4422800 | D30: =COUNTIF('2. Clean Data'!C3:C402,B30) -> 35 | E30: =IFERROR(C30/D30,0) -> 126365.72 | F30: =IFERROR((C30-C29)/C29,0) -> 0.3540398
B31: Dec | C31: =SUMIF('2. Clean Data'!C3:C402,B31,'2. Clean Data'!L3:L402) -> 3483486.5 | D31: =COUNTIF('2. Clean Data'!C3:C402,B31) -> 33 | E31: =IFERROR(C31/D31,0) -> 105560.2 | F31: =IFERROR((C31-C30)/C30,0) -> -0.21237984
B34: 🏆 E. Relationship Manager Performance
B35: Manager | C35: Total Portfolio ($) | D35: # Deals | E35: Avg Deal ($) | F35: Rank
B36: Sarah Chen | C36: =SUMIF('2. Clean Data'!I3:I402,B36,'2. Clean Data'!L3:L402) -> 9345429.5 | D36: =COUNTIF('2. Clean Data'!I3:I402,B36) -> 77 | E36: =IFERROR(C36/D36,0) -> 121369.21 | F36: =RANK(C36,C36:C40,0) -> 4
B37: James Patel | C37: =SUMIF('2. Clean Data'!I3:I402,B37,'2. Clean Data'!L3:L402) -> 9739146 | D37: =COUNTIF('2. Clean Data'!I3:I402,B37) -> 87 | E37: =IFERROR(C37/D37,0) -> 111944.21 | F37: =RANK(C37,C36:C40,0) -> 3
B38: Maria Lopez | C38: =SUMIF('2. Clean Data'!I3:I402,B38,'2. Clean Data'!L3:L402) -> 12070326 | D38: =COUNTIF('2. Clean Data'!I3:I402,B38) -> 91 | E38: =IFERROR(C38/D38,0) -> 132640.95 | F38: =RANK(C38,C36:C40,0) -> 1
B39: David Kim | C39: =SUMIF('2. Clean Data'!I3:I402,B39,'2. Clean Data'!L3:L402) -> 7339465.5 | D39: =COUNTIF('2. Clean Data'!I3:I402,B39) -> 64 | E39: =IFERROR(C39/D39,0) -> 114679.15 | F39: =RANK(C39,C36:C40,0) -> 5
B40: Rachel Moore | C40: =SUMIF('2. Clean Data'!I3:I402,B40,'2. Clean Data'!L3:L402) -> 9881403.2 | D40: =COUNTIF('2. Clean Data'!I3:I402,B40) -> 81 | E40: =IFERROR(C40/D40,0) -> 121992.63 | F40: =RANK(C40,C36:C40,0) -> 2

Sheet 4. Pivot Summary
A1: PIVOT-STYLE SUMMARY TABLES — Multi-Dimensional Analysis
B3: Pivot 1: Amount ($) by Branch vs. Product Category
B4: Branch / Category | C4: Deposits | D4: Loans | E4: Cards | F4: Row Total | J4: Risk / Segment | K4: Basic | L4: Standard | M4: Premium | N4: Row Total
B5: Downtown | C5: =SUMPRODUCT(('2. Clean Data'!F3:F402=B5)*('2. Clean Data'!H3:H402="Deposits")*('2. Clean Data'!L3:L402)) -> 4096489.8 | D5: =SUMPRODUCT(('2. Clean Data'!F3:F402=B5)*('2. Clean Data'!H3:H402="Loans")*('2. Clean Data'!L3:L402)) -> 3790254.7 | E5: =SUMPRODUCT(('2. Clean Data'!F3:F402=B5)*('2. Clean Data'!H3:H402="Cards")*('2. Clean Data'!L3:L402)) -> 1213707.8 | F5: =SUM(C5:E5) -> 9100452.4 | J5: Low | K5: =SUMPRODUCT(('2. Clean Data'!K3:K402=J5)*('2. Clean Data'!Q3:Q402="Basic")) -> 8 | L5: =SUMPRODUCT(('2. Clean Data'!K3:K402=J5)*('2. Clean Data'!Q3:Q402="Standard")) -> 46 | M5: =SUMPRODUCT(('2. Clean Data'!K3:K402=J5)*('2. Clean Data'!Q3:Q402="Premium")) -> 91 | N5: =SUM(K5:M5) -> 145
B6: Uptown | C6: =SUMPRODUCT(('2. Clean Data'!F3:F402=B6)*('2. Clean Data'!H3:H402="Deposits")*('2. Clean Data'!L3:L402)) -> 2372621.4 | D6: =SUMPRODUCT(('2. Clean Data'!F3:F402=B6)*('2. Clean Data'!H3:H402="Loans")*('2. Clean Data'!L3:L402)) -> 4856119.1 | E6: =SUMPRODUCT(('2. Clean Data'!F3:F402=B6)*('2. Clean Data'!H3:H402="Cards")*('2. Clean Data'!L3:L402)) -> 1161133.1 | F6: =SUM(C6:E6) -> 8389873.6 | J6: Medium | K6: =SUMPRODUCT(('2. Clean Data'!K3:K402=J6)*('2. Clean Data'!Q3:Q402="Basic")) -> 11 | L6: =SUMPRODUCT(('2. Clean Data'!K3:K402=J6)*('2. Clean Data'!Q3:Q402="Standard")) -> 50 | M6: =SUMPRODUCT(('2. Clean Data'!K3:K402=J6)*('2. Clean Data'!Q3:Q402="Premium")) -> 89 | N6: =SUM(K6:M6) -> 150
B7: Westside | C7: =SUMPRODUCT(('2. Clean Data'!F3:F402=B7)*('2. Clean Data'!H3:H402="Deposits")*('2. Clean Data'!L3:L402)) -> 3127370.4 | D7: =SUMPRODUCT(('2. Clean Data'!F3:F402=B7)*('2. Clean Data'!H3:H402="Loans")*('2. Clean Data'!L3:L402)) -> 5031558.2 | E7: =SUMPRODUCT(('2. Clean Data'!F3:F402=B7)*('2. Clean Data'!H3:H402="Cards")*('2. Clean Data'!L3:L402)) -> 1840824 | F7: =SUM(C7:E7) -> 9999752.6 | J7: High | K7: =SUMPRODUCT(('2. Clean Data'!K3:K402=J7)*('2. Clean Data'!Q3:Q402="Basic")) -> 10 | L7: =SUMPRODUCT(('2. Clean Data'!K3:K402=J7)*('2. Clean Data'!Q3:Q402="Standard")) -> 32 | M7: =SUMPRODUCT(('2. Clean Data'!K3:K402=J7)*('2. Clean Data'!Q3:Q402="Premium")) -> 63 | N7: =SUM(K7:M7) -> 105
B8: Eastgate | C8: =SUMPRODUCT(('2. Clean Data'!F3:F402=B8)*('2. Clean Data'!H3:H402="Deposits")*('2. Clean Data'!L3:L402)) -> 4866018.4 | D8: =SUMPRODUCT(('2. Clean Data'!F3:F402=B8)*('2. Clean Data'!H3:H402="Loans")*('2. Clean Data'!L3:L402)) -> 5116378.2 | E8: =SUMPRODUCT(('2. Clean Data'!F3:F402=B8)*('2. Clean Data'!H3:H402="Cards")*('2. Clean Data'!L3:L402)) -> 1251575.3 | F8: =SUM(C8:E8) -> 11233972
B9: Northpark | C9: =SUMPRODUCT(('2. Clean Data'!F3:F402=B9)*('2. Clean Data'!H3:H402="Deposits")*('2. Clean Data'!L3:L402)) -> 4324458.5 | D9: =SUMPRODUCT(('2. Clean Data'!F3:F402=B9)*('2. Clean Data'!H3:H402="Loans")*('2. Clean Data'!L3:L402)) -> 4198192.8 | E9: =SUMPRODUCT(('2. Clean Data'!F3:F402=B9)*('2. Clean Data'!H3:H402="Cards")*('2. Clean Data'!L3:L402)) -> 1129068.4 | F9: =SUM(C9:E9) -> 9651719.8
B10: Column Total | C10: =SUM(C5:C9) -> 18786959 | D10: =SUM(D5:D9) -> 22992503 | E10: =SUM(E5:E9) -> 6596308.7 | F10: =SUM(F5:F9) -> 48375770
J12: Pivot 2: Number of Deals by Risk Level vs. Customer Segment
